Workbook

Sheet Inprocess-POS
A1: Location | B1: Label No | C1: RM Code | D1: RM Name | E1: Document No | F1: Qty
A2: D/E (B) | B2: 2036 | C2: 3 | D2: 02XR-6H-P | E2: 25-1100868 | F2: 100
A3: D/E (B) | B3: 2041 | C3: 3 | D3: 02XR-6H-P | E3: 25-1100863 | F3: 100
A4: D/E (B) | B4: 2041 | C4: 5 | D4: 03XR-6H-P | E4: 25-1100863 | F4: 200
A5: D/E (B) | B5: 2039 | C5: 5 | D5: 03XR-6H-P | E5: 25-1100864 | F5: 200
A6: D/E (B) | B6: 2043 | C6: 5 | D6: 03XR-6H-P | E6: 25-1100284 | F6: 800
A7: D/E (B) | B7: 2036 | C7: 5 | D7: 03XR-6H-P | E7: 25-1100868 | F7: 200
A8: D/E (B) | B8: 2031 | C8: 5 | D8: 03XR-6H-P | E8: 25-1100870 | F8: 200
A9: MS-01 (L) | B9: 2204 | C9: 5 | D9: 03XR-6H-P | E9: 25-1101976 | F9: 5000
A10: MS-01 (L) | B10: 2220 | C10: 5 | D10: 03XR-6H-P | E10: 25-1101978 | F10: 4800
A11: MS-01 (L) | B11: 2197 | C11: 5 | D11: 03XR-6H-P | E11: 25-1101289 | F11: 4200
A12: MS-01 (C) | B12: 2248 | C12: 7 | D12: 04CZ-6H | E12: 25-1100945 | F12: 650
A13: MS-01 (L) | B13: 2215 | C13: 8 | D13: 04XR-6H-P | E13: 25-1101928 | F13: 2000
... A51: DECAM7 (B) | B51: 2185 | C51: 153 | D51: 2-353293-4 | E51: 25-1101880 | F51: 720
B52: 2501 | C52: 156 | D52: 2-353293-6 | E52: 25-1101116 | F52: 8000
A53: MS-01 (E) | B53: 2174 | C53: 156 | D53: 2-353293-6 | E53: 25-1101750 | F53: 2400
A54: MS-01 (E) | B54: 2176 | C54: 156 | D54: 2-353293-6 | E54: 25-1101729 | F54: 4000
B55: 2499 | C55: 156 | D55: 2-353293-6 | E55: 25-1101114 | F55: 8000
B56: 2500 | C56: 156 | D56: 2-353293-6 | E56: 25-1101112 | F56: 8000
A57: DECAM7 (D) | B57: 2413 | C57: 156 | D57: 2-353293-6 | E57: 25-1101610 | F57: 480
A58: D/E (I) | B58: 2055 | C58: 156 | D58: 2-353293-6 | E58: 25-1101748 | F58: 3600
A59: DECAM7 (D) | B59: 2418 | C59: 202 | D59: 3-353293-2 | E59: 25-1101174 | F59: 400
A60: MS-01 (F) | B60: 2004 | C60: 206 | D60: 3-353293-4 | E60: 25-1100709 | F60: 2050
A61: MS-01 (F) | B61: 2002 | C61: 206 | D61: 3-353293-4 | E61: 25-1100698 | F61: 1000
A62: MS-01 (F) | B62: 2001 | C62: 206 | D62: 3-353293-4 | E62: 25-1100828 | F62: 2550
A63: MS-01 (G) | B63: 2005 | C63: 213 | D63: 3-353293-8 | E63: 25-1101668 | F63: 3100
A64: DECAM7 (D) | B64: 2416 | C64: 213 | D64: 3-353293-8 | E64: 25-1101720 | F64: 800
A65: DECAM7 (E) | B65: 2160 | C65: 213 | D65: 3-353293-8 | E65: 25-1101663 | F65: 3250
A66: DECAM7 (F) | B66: 2003 | C66: 213 | D66: 3-353293-8 | E66: 25-1101673 | F66: 3400
A67: DECAM7 (D) | B67: 2406 | C67: 213 | D67: 3-353293-8 | E67: 25-1101608 | F67: 960
A68: DECAM7 (B) | B68: 2190 | C68: 222 | D68: 353293-6 | E68: 25-1101948 | F68: 100
... A91: MS-01 (A) | B91: 2188 | C91: 339 | D91: 9-292112-5 | E91: 25-1100393 | F91: 2000
B92: 2501 | C92: 383 | D92: GHR-06V-S | E92: 25-1101116 | F92: 8000
B93: 2500 | C93: 383 | D93: GHR-06V-S | E93: 25-1101112 | F93: 8000
B94: 2499 | C94: 383 | D94: GHR-06V-S | E94: 25-1101114 | F94: 8000
A95: D/E (B) | B95: 2035 | C95: 509 | D95: 06CK-6H-PC | E95: 25-1100869 | F95: 100
A96: D/E (G) | B96: 2073 | C96: 654 | D96: 1-2355088-5 | E96: 25-1100522 | F96: 4240
A97: D/E (G) | B97: 2078 | C97: 654 | D97: 1-2355088-5 | E97: 25-1100525 | F97: 7200
A98: MS-01 (A) | B98: 2188 | C98: 655 | D98: 1-2355088-7 | E98: 25-1100393 | F98: 2000
A99: MS-01 (G) | B99: 2005 | C99: 656 | D99: 1-2355088-9 | E99: 25-1101668 | F99: 3100
...

Sheet Inprocess-Semi
A1: Location | B1: Label No | C1: WIP Name | D1: WIP Qty | E1: Document No | F1: POS No | G1: RM Code | H1: RM Name | I1: Usage Qty
A2: DECAM7 (D) && AMP 1.5 (D) | B2: 2491 | C2: FM1-T942-000(005)-01 | D2: 1000 | E2: 25-1100164 | F2: 25-1100164 | G2: 213 | H2: 3-353293-8 | I2: 1000
A3: DECAM7 (D) && AMP 1.5 (D) | B3: 2408 | C3: FM1-T942-000(005)-01 | D3: 1000 | E3: 25-1100164 | F3: 25-1100164 | G3: 213 | H3: 3-353293-8 | I3: 1000
A4: DECAM7 (D) && AMP 1.5 (D) | B4: 2491 | C4: FM1-T942-000(005)-01 | D4: 1000 | E4: 25-1100164 | F4: 25-1100164 | G4: 219 | H4: 353293-3 | I4: 4000
A5: DECAM7 (D) && AMP 1.5 (D) | B5: 2408 | C5: FM1-T942-000(005)-01 | D5: 1000 | E5: 25-1100164 | F5: 25-1100164 | G5: 219 | H5: 353293-3 | I5: 4000
A6: DECAM7 (D) && AMP 1.5 (D) | B6: 2491 | C6: FM1-T942-000(005)-01 | D6: 1000 | E6: 25-1100164 | F6: 25-1100164 | G6: 156 | H6: 2-353293-6 | I6: 1000
A7: DECAM7 (D) && AMP 1.5 (D) | B7: 2408 | C7: FM1-T942-000(005)-01 | D7: 1000 | E7: 25-1100164 | F7: 25-1100164 | G7: 156 | H7: 2-353293-6 | I7: 1000
A8: DECAM7 (D) && AMP 1.5 (D) | B8: 2408 | C8: FM1-T942-000(005)-01 | D8: 1000 | E8: SD251122013 | F8: 25-1100164 | G8: 3462 | H8: UL10272-26 VLT(7/0.16) (KP) AMP | I8: 5589
A9: DECAM7 (D) && AMP 1.5 (D) | B9: 2491 | C9: FM1-T942-000(005)-01 | D9: 1000 | E9: SD251122013 | F9: 25-1100164 | G9: 3462 | H9: UL10272-26 VLT(7/0.16) (KP) AMP | I9: 5589
A10: CPR-ZERO (C) | B10: 2365 | C10: FM1-T748-000(006)-02 | D10: 10000 | E10: SD251125010 | F10: 25-1101235 | G10: 3464 | H10: UL10272-28 GRY(7/0.127) (KP) JST | I10: 1570
A11: CPR-ZERO (C) | B11: 2366 | C11: FM1-T748-000(006)-02 | D11: 6000 | E11: SD251125010 | F11: 25-1101235 | G11: 3464 | H11: UL10272-28 GRY(7/0.127) (KP) JST | I11: 942
A12: CPR-ZERO (C) | B12: 2366 | C12: FM1-T748-000(006)-02 | D12: 6000 | E12: SD251125010 | F12: 25-1101235 | G12: 1078 | H12: SSHL-003T-P0.2 | I12: 6000
A13: CPR-ZERO (C) | B13: 2365 | C13: FM1-T748-000(006)-02 | D13: 10000 | E13: SD251125010 | F13: 25-1101235 | G13: 1078 | H13: SSHL-003T-P0.2 | I13: 10000
... A1134: CPR-ZERO (A) | B1134: 2386 | C1134: D0E35301D-03 | D1134: 1550 | E1134: SD251125030 | F1134: 25-1101982 | G1134: 3016 | H1134: UL1007-18 YEL(41/0.16)(HR) | I1134: 1993.3

Sheet Inprocess-SD
A1: Location | B1: Label No | C1: Document No | D1: RM Code | E1: RM Name | F1: Qty
A2: CPR-ZERO (A) | B2: 2496 | C2: SD251125011 | D2: 3175 | E2: UL3683-16 WHT(55/0.18)(KR)(S.I) | F2: 17
A3: CPR-ZERO (B) | B3: 2453 | C3: SD251128029 | D3: 3487 | E3: UL10272-26 BLU(7/0.16)(KP) AMP | F3: 1878
A4: CPR-ZERO (A) | B4: 2496 | C4: SD251125011 | D4: 1058 | E4: SPS-51T-187 | F4: 258
A5: CPR-ZERO (A) | B5: 2496 | C5: SD251125011 | D5: 1067 | E5: SRA-51T-3 | F5: 1898
A6: CPR-ZERO (A) | B6: 2496 | C6: SD251125011 | D6: 1068 | E6: SRA-51T-4 | F6: 1492
A7: CPR-ZERO (A) | B7: 2496 | C7: SD251125011 | D7: 1073 | E7: SRICM-61GG-S0.6(LF)(SN) | F7: 464
A8: CPR-ZERO (A) | B8: 2496 | C8: SD251125011 | D8: 1106 | E8: SVSF-61T-S2.0 | F8: 71
A9: CPR-ZERO (A) | B9: 2447 | C9: SD251128026 | D9: 3007 | E9: UL1007-18 BLK(41/0.16)(HR) | F9: 12522
A10: SK-A20 (B) | B10: 2056 | C10: SD251128015 | D10: 3211 | E10: UL1061-28 BLK(7/0.127)(WD) | F10: 8281
A11: SK-A20 (B) | B11: 2056 | C11: SD251128015 | D11: 3212 | E11: UL1061-28 RED(7/0.127)(WD) | F11: 6736
A12: CPR-ZERO (A) | B12: 2496 | C12: SD251125011 | D12: 3567 | E12: UL1015-16 G/Y(54/0.18) (KP) | F12: 82
A13: CPR-ZERO (A) | B13: 2496 | C13: SD251125011 | D13: 3568 | E13: UL1015-16 BLK(54/0.18) (KP) | F13: 0
... A46: CPR-ZERO (A) | B46: 2496 | C46: SD251125011 | D46: 3140 | E46: UL3543-18 WHT(35/0.18)(KR)(D.I) | F46: 165

Sheet Inprocess-NG
A1: MCSeq No | B1: Document No | C1: POS No | D1: RM Code | E1: RM Name | F1: Qty
A2: MC1 | B2: 25-1101570 | C2: 25-1101570 | D2: 202 | E2: 3-353293-2 | F2: 10
A3: MC1 | B3: 25-1101355 | C3: SD251125011 | D3: 3140 | E3: UL3543-18 WHT(35/0.18)(KR)(D.I) | F3: 6.36
A4: MC1 | B4: 25-1101356 | C4: SD251125011 | D4: 3140 | E4: UL3543-18 WHT(35/0.18)(KR)(D.I) | F4: 10.15
A5: MC1 | B5: 25-1101645 | C5: SD251127026 | D5: 3456 | E5: UL1061-22 RED(17/0.16)(KP) | F5: 3.73
A6: MC1 | B6: 25-1101865 | C6: SD251127026 | D6: 3456 | E6: UL1061-22 RED(17/0.16)(KP) | F6: 4.86
A7: MC1 | B7: 25-1101817 | C7: SD251127026 | D7: 3456 | E7: UL1061-22 RED(17/0.16)(KP) | F7: 0.47
A8: MC1 | B8: 25-1102021 | C8: SD251127005 | D8: 3559 | E8: UL1007-24 YEL(11/0.16) (KP) | F8: 8.97
A9: MC1 | B9: 25-1101682 | C9: SD251127005 | D9: 3559 | E9: UL1007-24 YEL(11/0.16) (KP) | F9: 0.5
A10: MC1 | B10: 25-1101603 | C10: SD251127005 | D10: 3559 | E10: UL1007-24 YEL(11/0.16) (KP) | F10: 0.5
A11: MC1 | B11: 25-1101687 | C11: SD251127005 | D11: 3559 | E11: UL1007-24 YEL(11/0.16) (KP) | F11: 0.5
A12: MC1 | B12: 25-1102016 | C12: SD251127005 | D12: 3559 | E12: UL1007-24 YEL(11/0.16) (KP) | F12: 0.5
A13: MC1 | B13: 25-1101600 | C13: SD251127005 | D13: 3559 | E13: UL1007-24 YEL(11/0.16) (KP) | F13: 5.03
... A125: MC1 | B125: 25-1100980 | C125: SD251125014 | D125: 3463 | E125: UL10272-26 YEL(7/0.16)(KP) JST | F125: 33.21
A126: MC1 | D126: 3463 | E126: UL10272-26 YEL(7/0.16)(KP) JST | F126: 0.3
A127: MC1 | B127: 25-1100586 | C127: SD251125014 | D127: 3463 | E127: UL10272-26 YEL(7/0.16)(KP) JST | F127: 29.06
A128: MC1 | B128: 25-1101616 | C128: SD251128029 | D128: 3487 | E128: UL10272-26 BLU(7/0.16)(KP) AMP | F128: 29.14
A129: MC1 | B129: 25-1101618 | C129: SD251128029 | D129: 3487 | E129: UL10272-26 BLU(7/0.16)(KP) AMP | F129: 7.69
A130: MC1 | B130: 25-1101602 | C130: SD251127005 | D130: 3503 | E130: UL1007-24 BRN(11/0.16) (KP) | F130: 0.51
A131: MC1 | B131: 25-1101049 | C131: SD251127012 | D131: 3503 | E131: UL1007-24 BRN(11/0.16) (KP) | F131: 20.2
A132: MC1 | B132: 25-1101684 | C132: SD251127005 | D132: 3503 | E132: UL1007-24 BRN(11/0.16) (KP) | F132: 0.51
A133: MC1 | B133: 25-1102018 | C133: SD251127005 | D133: 3503 | E133: UL1007-24 BRN(11/0.16) (KP) | F133: 3.96
A134: MC1 | B134: 25-1101679 | C134: SD251127005 | D134: 3503 | E134: UL1007-24 BRN(11/0.16) (KP) | F134: 0.51
A135: MC1 | B135: 25-1102013 | C135: SD251127005 | D135: 3503 | E135: UL1007-24 BRN(11/0.16) (KP) | F135: 0.51
A136: MC1 | B136: 25-1101604 | C136: SD251127005 | D136: 3531 | E136: UL1007-24 VLT(11/0.16) (KP) | F136: 2.53
A137: MC1 | B137: 25-1101599 | C137: SD251127005 | D137: 3531 | E137: UL1007-24 VLT(11/0.16) (KP) | F137: 5.05
A138: MC1 | B138: 25-1100580 | C138: SD251125011 | D138: 3568 | E138: UL1015-16 BLK(54/0.18) (KP) | F138: 15.2
... A219: MC1 | B219: 25-1101652 | C219: SD251128019 | D219: 3571 | E219: UL1061-22 WHT(7/0.26T) (HR) | F219: 6.89

Sheet Other
A1: RM Code | B1: RM Name | C1: Qty | D1: Remarks

Sheet Inprocess-Combine
A1: Marunix (Cambodia) Co.,Ltd.
A2: Inventory Report
A3: Location
A4: Date
A5: =COUNTA(A8:A2000) -> 151 | B5: =COUNTIF(G8:G2000,0) -> 139 | C5: =COUNTIF(G8:G2000,">0") -> 7 | D5: =COUNTIF(G8:G2000,"<0") -> 5
B6: =B5/$A$5 -> 0.9205298 | C6: =C5/$A$5 -> 0.046357616 | D6: =D5/$A$5 -> 0.033112583
A7: RM Code | B7: RM Description | C7: RM Type | D7: Inventory | E7: Other | F7: Sub-Sys | G7: GAP
A8: 3 | B8: 02XR-6H-P | C8: Connector | D8: =200+4240+0+0 -> 4440 | E8: =SUMIF(Other!A:A,A8,Other!C:C) -> 0 | F8: 4440 | G8: =D8+E8-F8 -> 0
A9: 4 | B9: 03CZ-6H | C9: Connector | D9: =0+4000+0+40 -> 4040 | E9: =SUMIF(Other!A:A,A9,Other!C:C) -> 0 | F9: 4040 | G9: =D9+E9-F9 -> 0
A10: 5 | B10: 03XR-6H-P | C10: Connector | D10: =15600+14720+0+0 -> 30320 | E10: =SUMIF(Other!A:A,A10,Other!C:C) -> 0 | F10: 30320 | G10: =D10+E10-F10 -> 0
A11: 7 | B11: 04CZ-6H | C11: Connector | D11: =650+0+0+20 -> 670 | E11: =SUMIF(Other!A:A,A11,Other!C:C) -> 0 | F11: 670 | G11: =D11+E11-F11 -> 0
A12: 8 | B12: 04XR-6H-P | C12: Connector | D12: =2300+3480+0+0 -> 5780 | E12: =SUMIF(Other!A:A,A12,Other!C:C) -> 0 | F12: 5780 | G12: =D12+E12-F12 -> 0
A13: 9 | B13: 05CZ-6H | C13: Connector | D13: =20000+8000+0+0 -> 28000 | E13: =SUMIF(Other!A:A,A13,Other!C:C) -> 0 | F13: 28000 | G13: =D13+E13-F13 -> 0
A14: 11 | B14: 06CZ-6H | C14: Connector | D14: =200+5000+0+10 -> 5210 | E14: =SUMIF(Other!A:A,A14,Other!C:C) -> 0 | F14: 5210 | G14: =D14+E14-F14 -> 0
A15: 14 | B15: 07CZ-6H | C15: Connector | D15: =200+0+0+20 -> 220 | E15: =SUMIF(Other!A:A,A15,Other!C:C) -> 0 | F15: 220 | G15: =D15+E15-F15 -> 0
A16: 19 | B16: 09CZ-6H | C16: Connector | D16: =0+3000+0+0 -> 3000 | E16: =SUMIF(Other!A:A,A16,Other!C:C) -> 0 | F16: 3000 | G16: =D16+E16-F16 -> 0
A17: 77 | B17: 13CSR-8PK(N) | C17: Connector | D17: =200+0+0+0 -> 200 | E17: =SUMIF(Other!A:A,A17,Other!C:C) -> 0 | F17: 200 | G17: =D17+E17-F17 -> 0
A18: 78 | B18: 13CZ-6H | C18: Connector | D18: =7700+0+0+0 -> 7700 | E18: =SUMIF(Other!A:A,A18,Other!C:C) -> 0 | F18: 7700 | G18: =D18+E18-F18 -> 0
A19: 79 | B19: 14CZ-6H | C19: Connector | D19: =650+0+0+0 -> 650 | E19: =SUMIF(Other!A:A,A19,Other!C:C) -> 0 | F19: 650 | G19: =D19+E19-F19 -> 0
A20: 94 | B20: 173977-2 | C20: Connector | D20: =0+200+0+0 -> 200 | E20: =SUMIF(Other!A:A,A20,Other!C:C) -> 0 | F20: 200 | G20: =D20+E20-F20 -> 0
A21: 95 | B21: 173977-3 | C21: Connector | D21: =6000+1200+0+0 -> 7200 | E21: =SUMIF(Other!A:A,A21,Other!C:C) -> 0 | F21: 7200 | G21: =D21+E21-F21 -> 0
A22: 97 | B22: 173977-4 | C22: Connector | D22: =6160+1920+0+0 -> 8080 | E22: =SUMIF(Other!A:A,A22,Other!C:C) -> 0 | F22: 8080 | G22: =D22+E22-F22 -> 0
A23: 102 | B23: 173977-7 | C23: Connector | D23: =0+5500+0+0 -> 5500 | E23: =SUMIF(Other!A:A,A23,Other!C:C) -> 0 | F23: 5500 | G23: =D23+E23-F23 -> 0
A24: 118 | B24: 18CZ-6H | C24: Connector | D24: =850+0+0+0 -> 850 | E24: =SUMIF(Other!A:A,A24,Other!C:C) -> 0 | F24: 850 | G24: =D24+E24-F24 -> 0
A25: 135 | B25: 2-173977-3 | C25: Connector | D25: =0+100+0+0 -> 100 | E25: =SUMIF(Other!A:A,A25,Other!C:C) -> 0 | F25: 100 | G25: =D25+E25-F25 -> 0
A26: 149 | B26: 2-353293-2 | C26: Connector | D26: =0+9300+0+640 -> 9940 | E26: =SUMIF(Other!A:A,A26,Other!C:C) -> 0 | F26: 9940 | G26: =D26+E26-F26 -> 0
A27: 151 | B27: 2-353293-3 | C27: Connector | D27: =18060+13910+0+0 -> 31970 | E27: =SUMIF(Other!A:A,A27,Other!C:C) -> 0 | F27: 31970 | G27: =D27+E27-F27 -> 0
A28: 153 | B28: 2-353293-4 | C28: Connector | D28: =820+290+0+30 -> 1140 | E28: =SUMIF(Other!A:A,A28,Other!C:C) -> 0 | F28: 1140 | G28: =D28+E28-F28 -> 0
A29: 155 | B29: 2-353293-5 | C29: Connector | D29: =0+1100+0+40 -> 1140 | E29: =SUMIF(Other!A:A,A29,Other!C:C) -> 0 | F29: 1140 | G29: =D29+E29-F29 -> 0
A30: 156 | B30: 2-353293-6 | C30: Connector | D30: =34480+55380+0+290 -> 90150 | E30: =SUMIF(Other!A:A,A30,Other!C:C) -> 0 | F30: 83750 | G30: =D30+E30-F30 -> 6400
A31: 160 | B31: 2-353293-8 | C31: Connector | D31: =0+7000+0+0 -> 7000 | E31: =SUMIF(Other!A:A,A31,Other!C:C) -> 0 | F31: 7000 | G31: =D31+E31-F31 -> 0
A32: 161 | B32: 31CSR-8PK(N) | C32: Connector | D32: =0+160+0+0 -> 160 | E32: =SUMIF(Other!A:A,A32,Other!C:C) -> 0 | F32: 160 | G32: =D32+E32-F32 -> 0
A33: 162 | B33: 2-353293-9 | C33: Connector | D33: =0+12400+0+20 -> 12420 | E33: =SUMIF(Other!A:A,A33,Other!C:C) -> 0 | F33: 12420 | G33: =D33+E33-F33 -> 0
A34: 190 | B34: 15CSR-8PK(N) | C34: Connector | D34: =0+160+0+0 -> 160 | E34: =SUMIF(Other!A:A,A34,Other!C:C) -> 0 | F34: 160 | G34: =D34+E34-F34 -> 0
A35: 200 | B35: 3-353293-0 | C35: Connector | D35: =0+250+0+0 -> 250 | E35: =SUMIF(Other!A:A,A35,Other!C:C) -> 0 | F35: 250 | G35: =D35+E35-F35 -> 0
A36: 201 | B36: 3-353293-1 | C36: Connector | D36: =0+1600+0+0 -> 1600 | E36: =SUMIF(Other!A:A,A36,Other!C:C) -> 0 | F36: 1600 | G36: =D36+E36-F36 -> 0
A37: 202 | B37: 3-353293-2 | C37: Connector | D37: =400+280+0+10 -> 690 | E37: =SUMIF(Other!A:A,A37,Other!C:C) -> 0 | F37: 694 | G37: =D37+E37-F37 -> -4
A38: 206 | B38: 3-353293-4 | C38: Connector | D38: =5600+300+0+0 -> 5900 | E38: =SUMIF(Other!A:A,A38,Other!C:C) -> 0 | F38: 5900 | G38: =D38+E38-F38 -> 0
A39: 208 | B39: 3-353293-5 | C39: Connector | D39: =0+1000+0+0 -> 1000 | E39: =SUMIF(Other!A:A,A39,Other!C:C) -> 0 | F39: 1000 | G39: =D39+E39-F39 -> 0
A40: 209 | B40: 3-353293-6 | C40: Connector | D40: =0+700+0+0 -> 700 | E40: =SUMIF(Other!A:A,A40,Other!C:C) -> 0 | F40: 700 | G40: =D40+E40-F40 -> 0
...
