Workbook

Sheet Inprocess-POS
A1: Location | B1: Label No | C1: RM Code | D1: RM Name | E1: Document No | F1: Qty
A2: MS-01 (D) | B2: 2252 | C2: 200 | D2: 3-353293-0 | E2: 26-0201480 | F2: 3600
A3: DECAM7 (C) | B3: 2280 | C3: 200 | D3: 3-353293-0 | E3: 26-0201456 | F3: 450
A4: MS-01 (E) | B4: 2352 | C4: 202 | D4: 3-353293-2 | E4: 26-0201124 | F4: 4500
A5: DECAM7 (A) | B5: 2340 | C5: 206 | D5: 3-353293-4 | E5: 26-0201126 | F5: 2800
A6: DECAM7 (A) | B6: 2341 | C6: 206 | D6: 3-353293-4 | E6: 26-0201128 | F6: 4200
A7: DECAM7 (F) | B7: 2379 | C7: 206 | D7: 3-353293-4 | E7: 26-0201495 | F7: 2300
A8: MS-01 (F) | B8: 2003 | C8: 206 | D8: 3-353293-4 | E8: 26-0201243 | F8: 2600
A9: DECAM7 (C) | B9: 2297 | C9: 206 | D9: 3-353293-4 | E9: 26-0201470 | F9: 450
A10: MS-01 (G) | B10: 2063 | C10: 208 | D10: 3-353293-5 | E10: 26-0201580 | F10: 2350
A11: DECAM7 (E) | B11: 2369 | C11: 209 | D11: 3-353293-6 | E11: 26-0201252 | F11: 1700
A12: DECAM7 (D) | B12: 2210 | C12: 213 | D12: 3-353293-8 | E12: 26-0201060 | F12: 1280
A13: DECAM7 (D) | B13: 2214 | C13: 213 | D13: 3-353293-8 | E13: 26-0201318 | F13: 960
... A51: JAM07_SDII (C) | B51: 2397 | C51: 102 | D51: 173977-7 | E51: 26-0201182 | F51: 2000
B52: 2404 | C52: 102 | D52: 173977-7 | E52: 26-0201185 | F52: 3000
A53: MS-01 (H) | B53: 2088 | C53: 117 | D53: 17CZ-6H | E53: 26-0201430 | F53: 1100
A54: DECAM7 (A) | B54: 2342 | C54: 149 | D54: 2-353293-2 | E54: 26-0201348 | F54: 2000
A55: DECAM7 (A) | B55: 2344 | C55: 149 | D55: 2-353293-2 | E55: 26-0201353 | F55: 1500
A56: DECAM7 (D) | B56: 2210 | C56: 149 | D56: 2-353293-2 | E56: 26-0201060 | F56: 3840
A57: DECAM7 (D) | B57: 2210 | C57: 151 | D57: 2-353293-3 | E57: 26-0201060 | F57: 1280
A58: DECAM7 (D) | B58: 2213 | C58: 151 | D58: 2-353293-3 | E58: 26-0201420 | F58: 400
A59: DECAM7 (D) | B59: 2215 | C59: 151 | D59: 2-353293-3 | E59: 26-0201320 | F59: 960
A60: DECAM7 (F) | B60: 2379 | C60: 151 | D60: 2-353293-3 | E60: 26-0201495 | F60: 2300
A61: DECAM7 (C) | B61: 2298 | C61: 151 | D61: 2-353293-3 | E61: 26-0201234 | F61: 1600
A62: DECAM7 (C) | B62: 2300 | C62: 151 | D62: 2-353293-3 | E62: 26-0201223 | F62: 1600
A63: D/E (I) | B63: 2115 | C63: 151 | D63: 2-353293-3 | E63: 26-0201425 | F63: 7800
A64: MS-01 (E) | B64: 2351 | C64: 151 | D64: 2-353293-3 | E64: 26-0201472 | F64: 450
... A173: & YA-1A (B) | B173: 2408 | C173: 1156 | D173: CE-550V(SU) | E173: 26-0201104 | F173: 300

Sheet Inprocess-Semi
A1: Location | B1: Label No | C1: WIP Name | D1: WIP Qty | E1: Document No | F1: POS No | G1: RM Code | H1: RM Name | I1: Usage Qty
A2: DECAM7 (C) | B2: 2270 | C2: ADXDN10B02D-07 | D2: 450 | E2: 26-0201458 | F2: 26-0201458 | G2: 153 | H2: 2-353293-4 | I2: 450
A3: MS-01 (B) | B3: 2073 | C3: D0E35300D-07 | D3: 2050 | E3: 26-0201446 | F3: 26-0201446 | G3: 153 | H3: 2-353293-4 | I3: 2050
A4: MS-01 (D) | B4: 2251 | C4: AA7NN10K01B-02 | D4: 500 | E4: 26-0201267 | F4: 26-0201267 | G4: 153 | H4: 2-353293-4 | I4: 500
A5: MS-01 (D) | B5: 2282 | C5: FM2-B952-000(008)-01 | D5: 200 | E5: 26-0200980 | F5: 26-0200980 | G5: 155 | H5: 2-353293-5 | I5: 200
A6: DECAM7 (D) | B6: 2231 | C6: FM2-D839-000(010)-01 | D6: 3000 | E6: 26-0201083 | F6: 26-0201083 | G6: 155 | H6: 2-353293-5 | I6: 3000
A7: DECAM7 (D) | B7: 2186 | C7: QM7-5404-000(004)-01 | D7: 200 | E7: 26-0201308 | F7: 26-0201308 | G7: 155 | H7: 2-353293-5 | I7: 400
A8: CPR-ZERO (C) | B8: 2401 | C8: QM7-5411-000(006)-01 | D8: 160 | E8: 26-0201057 | F8: 26-0201057 | G8: 161 | H8: 31CSR-8PK(N) | I8: 320
A9: CPR-ZERO (C) | B9: 2403 | C9: QM7-5410-000(005)-01 | D9: 100 | E9: 26-0201054 | F9: 26-0201054 | G9: 161 | H9: 31CSR-8PK(N) | I9: 200
A10: DECAM7 (D) && AMP 2.0 (E) | B10: 2092 | C10: FM2-A956-000(013)-01 | D10: 3000 | E10: 26-0200149 | F10: 26-0200149 | G10: 211 | H10: 3-353293-7 | I10: 3000
A11: DECAM7 (D) | B11: 2033 | C11: FM2-A956-000(013)-01 | D11: 1000 | E11: 26-0201070 | F11: 26-0201070 | G11: 211 | H11: 3-353293-7 | I11: 1000
A12: DECAM7 (D) | B12: 2134 | C12: FM2-A956-000(013)-01 | D12: 1000 | E12: 26-0201070 | F12: 26-0201070 | G12: 211 | H12: 3-353293-7 | I12: 1000
A13: DECAM7 (D) | B13: 2030 | C13: FM2-A956-000(013)-01 | D13: 1000 | E13: 26-0201070 | F13: 26-0201070 | G13: 211 | H13: 3-353293-7 | I13: 1000
... A838: CPR-ZERO (D) && SATC-20 (B) | B838: 2285 | C838: FM4-G806-000(003)-01 | D838: 3000 | E838: SD260216032 | F838: 26-0201005 | G838: 3586 | H838: UL10913-22 BLK(17/0.16) (XY) | I838: 1062

Sheet Inprocess-SD
A1: Location | B1: Label No | C1: Document No | D1: RM Code | E1: RM Name | F1: Qty
A2: MS-01 (B) | B2: 2219 | C2: SD260220040 | D2: 3202 | E2: UL10272-26 BLU(7/0.16)(HR)AMP | F2: 72318
A3: DECAM7 (F) | B3: 2372 | C3: SD260220046 | D3: 3202 | E3: UL10272-26 BLU(7/0.16)(HR)AMP | F3: 27625
A4: MS-01 (A) | B4: 2054 | C4: SD260221009 | D4: 3202 | E4: UL10272-26 BLU(7/0.16)(HR)AMP | F4: 76324
A5: MS-01 (L) | B5: 2337 | C5: SD260220018 | D5: 3210 | E5: UL11079-26 ORG(7/0.16)(HR)JST | F5: 68455
A6: JAM07_SDII (D) | B6: 2411 | C6: SD260220009 | D6: 3559 | E6: UL1007-24 YEL(11/0.16) (KP) | F6: 1643
A7: JAM07_SDII (D) | B7: 2411 | C7: SD260220009 | D7: 3563 | E7: UL1007-24 BLU(11/0.16) (KP) | F7: 2416
A8: CPR-ZERO (A) | B8: 2392 | C8: SD260220017 | D8: 3565 | E8: UL1015-14 BLK(41/0.254) (KP) | F8: 1029
A9: CPR-ZERO (A) | B9: 2390 | C9: SD260220042 | D9: 3565 | E9: UL1015-14 BLK(41/0.254) (KP) | F9: 1200
A10: CPR-ZERO (A) | B10: 2392 | C10: SD260220017 | D10: 3566 | E10: UL1015-14 WHT(41/0.254) (KP) | F10: 415
A11: CPR-ZERO (A) | B11: 2390 | C11: SD260220042 | D11: 3566 | E11: UL1015-14 WHT(41/0.254) (KP) | F11: 1200
A12: JAM07_SDII (D) | B12: 2411 | C12: SD260220009 | D12: 3573 | E12: UL1007-24 RED(11/0.16) (KP) | F12: 1852
A13: JAM07_SDII (D) | B13: 2411 | C13: SD260220009 | D13: 3574 | E13: UL1007-24 GRN(11/0.16) (KP) | F13: 1554
... A77: JAM07_SDII (D) | B77: 2411 | C77: SD260220009 | D77: 3531 | E77: UL1007-24 VLT(11/0.16) (KP) | F77: 681

Sheet Inprocess-NG
A1: MCSeq No | B1: Document No | C1: POS No | D1: RM Code | E1: RM Name | F1: Qty
A2: MC1 | B2: 26-0200825 | C2: 26-0200825 | D2: 7 | E2: 04CZ-6H | F2: 8
A3: MC1 | B3: 26-0200375 | C3: 26-0200375 | D3: 7 | E3: 04CZ-6H | F3: 32
A4: MC1 | B4: 26-0200388 | C4: 26-0200388 | D4: 11 | E4: 06CZ-6H | F4: 12
A5: MC1 | B5: 26-0201436 | C5: 26-0201436 | D5: 213 | E5: 3-353293-8 | F5: 40
A6: MC1 | B6: 26-0201586 | C6: SD260220017 | D6: 1068 | E6: SRA-51T-4 | F6: 270
A7: MC1 | B7: 26-0201411 | C7: SD260220045 | D7: 3520 | E7: UL1007-20 BLU(21/0.18) (KP) | F7: 2.57
A8: MC1 | B8: 26-0201413 | C8: SD260220045 | D8: 3520 | E8: UL1007-20 BLU(21/0.18) (KP) | F8: 0.64
A9: MC1 | B9: 26-0200827 | C9: 26-0200827 | D9: 4 | E9: 03CZ-6H | F9: 7
A10: MC1 | B10: 26-0200388 | C10: 26-0200388 | D10: 4 | E10: 03CZ-6H | F10: 18
A11: MC1 | B11: 26-0200743 | C11: 26-0200743 | D11: 78 | E11: 13CZ-6H | F11: 2
A12: MC1 | B12: 26-0103211 | C12: 26-0103211 | D12: 153 | E12: 2-353293-4 | F12: 43
A13: MC1 | B13: 26-0201224 | C13: SD260220041 | D13: 3461 | E13: UL1061-26 GRY(7/0.160) (KP) | F13: 56.15
... A157: MC1 | B157: 26-0200985 | C157: SD260220024 | D157: 1121 | E157: SXA-001T-P0.6 | F157: 23
A158: MC1 | C158: 26-0100888 | D158: 2237 | E158: SUMITUBE K2 1/4 CLR | F158: 1
A159: MC1 | C159: 26-0100893 | D159: 2237 | E159: SUMITUBE K2 1/4 CLR | F159: 1
A160: MC1 | B160: 26-0103205 | C160: SD260207014 | D160: 3052 | E160: UL10272-26 WHT(7/0.16)(HR)AMP | F160: 81.73
A161: MC1 | B161: 26-0103211 | C161: SD260207014 | D161: 3052 | E161: UL10272-26 WHT(7/0.16)(HR)AMP | F161: 120.75
A162: MC1 | B162: 26-0103212 | C162: SD260207014 | D162: 3052 | E162: UL10272-26 WHT(7/0.16)(HR)AMP | F162: 156.52
A163: MC1 | B163: 26-0201085 | C163: SD260219020 | D163: 3052 | E163: UL10272-26 WHT(7/0.16)(HR)AMP | F163: 257
A164: MC1 | B164: 26-0201499 | C164: SD260220040 | D164: 3202 | E164: UL10272-26 BLU(7/0.16)(HR)AMP | F164: 845.12
A165: MC1 | B165: 26-0201092 | C165: SD260220046 | D165: 3202 | E165: UL10272-26 BLU(7/0.16)(HR)AMP | F165: 25.38
A166: MC1 | B166: 26-0201436 | C166: SD260220003 | D166: 3202 | E166: UL10272-26 BLU(7/0.16)(HR)AMP | F166: 507.62
A167: MC1 | B167: 26-0201361 | C167: SD260220009 | D167: 3523 | E167: UL1007-24 ORG(11/0.16)​(KP) | F167: 0.51
A168: MC1 | B168: 26-0201313 | C168: SD260220009 | D168: 3523 | E168: UL1007-24 ORG(11/0.16)​(KP) | F168: 8.93
A169: MC1 | B169: 26-0201366 | C169: SD260220009 | D169: 3523 | E169: UL1007-24 ORG(11/0.16)​(KP) | F169: 0.77
A170: MC1 | B170: 26-0200544 | C170: 26-0200544 | D170: 117 | E170: 17CZ-6H | F170: 6
A171: MC2 | B171: 26-0200031 | C171: 26-0200031 | D171: 156 | E171: 2-353293-6 | F171: 7
... A189: MC1 | B189: 26-0201398 | C189: SD260220033 | D189: 3462 | E189: UL10272-26 VLT(7/0.16) (KP) AMP | F189: 86.74
A190: MC1 | D190: 3462 | E190: UL10272-26 VLT(7/0.16) (KP) AMP | F190: 44.87
A191: MC1 | B191: 26-0201467 | C191: SD260221006 | D191: 3462 | E191: UL10272-26 VLT(7/0.16) (KP) AMP | F191: 121.26
A192: MC5 | B192: 25-0603257NG01 | C192: SD250730019 | D192: 3462 | E192: UL10272-26 VLT(7/0.16) (KP) AMP | F192: 20.671
A193: MC1 | B193: 26-0201455 | C193: SD260220047 | D193: 3462 | E193: UL10272-26 VLT(7/0.16) (KP) AMP | F193: 23.96
A194: MC1 | B194: 26-0201425 | C194: SD260219025 | D194: 3462 | E194: UL10272-26 VLT(7/0.16) (KP) AMP | F194: 72
A195: MC1 | B195: 26-0201358 | C195: SD260220009 | D195: 3563 | E195: UL1007-24 BLU(11/0.16) (KP) | F195: 3.06
A196: MC1 | B196: 26-0201310 | C196: SD260220009 | D196: 3563 | E196: UL1007-24 BLU(11/0.16) (KP) | F196: 76.94
A197: MC1 | B197: 26-0201585 | C197: SD260220017 | D197: 3566 | E197: UL1015-14 WHT(41/0.254) (KP) | F197: 10.48

Sheet Other
A1: RM Code | B1: RM Description | C1: RM Type | D1: GAP Qty | E1: Inventory Adding | F1: Remark
A2: 95 | B2: 173977-3 | C2: Connector | D2: -18 | E2: =D2*(-1) -> 18 | F2: Not yet adjust NG in process
A3: 322 | B3: 8-292112-2 | C3: Connector | D3: -50 | E3: =D3*(-1) -> 50 | F3: Not yet adjust NG in process
A4: 328 | B4: 8-292112-5 | C4: Connector | D4: -9 | E4: =D4*(-1) -> 9 | F4: Not yet adjust NG in process
A5: 3048 | B5: UL10272-26 VLT(7/0.16)(HR)AMP | C5: Wire | D5: 3 | E5: =D5*(-1) -> -3 | F5: SD in process not yet finish

Sheet Inprocess-Combine
A1: Marunix (Cambodia) Co.,Ltd.
A2: Inventory Report
A3: Location
A4: Date
A5: =COUNTA(A8:A151) -> 144 | B5: =COUNTIF(H8:H151,0) -> 144 | C5: =COUNTIF(H8:H151,">0") -> 0 | D5: =COUNTIF(H8:H151,"<0") -> 0
B6: =B5/A5 -> 1 | C6: =C5/A5 -> 0 | D6: =D5/A5 -> 0
A7: RM Code | B7: RM Description | C7: RM Type | D7: Inventory | E7: Other Case | F7: Final Inventory | G7: Sub-Sys | H7: GAP
A8: 3 | B8: 02XR-6H-P | C8: Connector | D8: =900+0+0+0 -> 900 | E8: =IFERROR(VLOOKUP(A8,Other!A:E,5,0),0) -> 0 | F8: =D8+E8 -> 900 | G8: 900 | H8: =F8-G8 -> 0
A9: 4 | B9: 03CZ-6H | C9: Connector | D9: =380+0+0+25 -> 405 | E9: =IFERROR(VLOOKUP(A9,Other!A:E,5,0),0) -> 0 | F9: =D9+E9 -> 405 | G9: 405 | H9: =F9-G9 -> 0
A10: 5 | B10: 03XR-6H-P | C10: Connector | D10: =3100+0+0+0 -> 3100 | E10: =IFERROR(VLOOKUP(A10,Other!A:E,5,0),0) -> 0 | F10: =D10+E10 -> 3100 | G10: 3100 | H10: =F10-G10 -> 0
A11: 7 | B11: 04CZ-6H | C11: Connector | D11: =0+0+0+40 -> 40 | E11: =IFERROR(VLOOKUP(A11,Other!A:E,5,0),0) -> 0 | F11: =D11+E11 -> 40 | G11: 40 | H11: =F11-G11 -> 0
A12: 8 | B12: 04XR-6H-P | C12: Connector | D12: =27100+12000+0+40 -> 39140 | E12: =IFERROR(VLOOKUP(A12,Other!A:E,5,0),0) -> 0 | F12: =D12+E12 -> 39140 | G12: 39140 | H12: =F12-G12 -> 0
A13: 9 | B13: 05CZ-6H | C13: Connector | D13: =36180+1350+0+135 -> 37665 | E13: =IFERROR(VLOOKUP(A13,Other!A:E,5,0),0) -> 0 | F13: =D13+E13 -> 37665 | G13: 37665 | H13: =F13-G13 -> 0
A14: 11 | B14: 06CZ-6H | C14: Connector | D14: =540+0+0+12 -> 552 | E14: =IFERROR(VLOOKUP(A14,Other!A:E,5,0),0) -> 0 | F14: =D14+E14 -> 552 | G14: 552 | H14: =F14-G14 -> 0
A15: 13 | B15: 06XR-6H-P | C15: Connector | D15: =2650+2600+0+10 -> 5260 | E15: =IFERROR(VLOOKUP(A15,Other!A:E,5,0),0) -> 0 | F15: =D15+E15 -> 5260 | G15: 5260 | H15: =F15-G15 -> 0
A16: 14 | B16: 07CZ-6H | C16: Connector | D16: =0+3600+0+164 -> 3764 | E16: =IFERROR(VLOOKUP(A16,Other!A:E,5,0),0) -> 0 | F16: =D16+E16 -> 3764 | G16: 3764 | H16: =F16-G16 -> 0
A17: 17 | B17: 08CZ-6H | C17: Connector | D17: =0+0+0+17 -> 17 | E17: =IFERROR(VLOOKUP(A17,Other!A:E,5,0),0) -> 0 | F17: =D17+E17 -> 17 | G17: 17 | H17: =F17-G17 -> 0
A18: 19 | B18: 09CZ-6H | C18: Connector | D18: =990+0+0+0 -> 990 | E18: =IFERROR(VLOOKUP(A18,Other!A:E,5,0),0) -> 0 | F18: =D18+E18 -> 990 | G18: 990 | H18: =F18-G18 -> 0
A19: 61 | B19: 12CZ-6H | C19: Connector | D19: =0+0+0+22 -> 22 | E19: =IFERROR(VLOOKUP(A19,Other!A:E,5,0),0) -> 0 | F19: =D19+E19 -> 22 | G19: 22 | H19: =F19-G19 -> 0
A20: 70 | B20: 1-353293-8 | C20: Connector | D20: =450+0+0+0 -> 450 | E20: =IFERROR(VLOOKUP(A20,Other!A:E,5,0),0) -> 0 | F20: =D20+E20 -> 450 | G20: 450 | H20: =F20-G20 -> 0
A21: 78 | B21: 13CZ-6H | C21: Connector | D21: =0+0+0+2 -> 2 | E21: =IFERROR(VLOOKUP(A21,Other!A:E,5,0),0) -> 0 | F21: =D21+E21 -> 2 | G21: 2 | H21: =F21-G21 -> 0
A22: 87 | B22: 15CZ-6H | C22: Connector | D22: =630+450+0+45 -> 1125 | E22: =IFERROR(VLOOKUP(A22,Other!A:E,5,0),0) -> 0 | F22: =D22+E22 -> 1125 | G22: 1125 | H22: =F22-G22 -> 0
A23: 89 | B23: 16CZ-6H | C23: Connector | D23: =200+0+0+0 -> 200 | E23: =IFERROR(VLOOKUP(A23,Other!A:E,5,0),0) -> 0 | F23: =D23+E23 -> 200 | G23: 200 | H23: =F23-G23 -> 0
A24: 94 | B24: 173977-2 | C24: Connector | D24: =11050+5700+0+0 -> 16750 | E24: =IFERROR(VLOOKUP(A24,Other!A:E,5,0),0) -> 0 | F24: =D24+E24 -> 16750 | G24: 16750 | H24: =F24-G24 -> 0
A25: 95 | B25: 173977-3 | C25: Connector | D25: =18000+26300+0+0 -> 44300 | E25: =IFERROR(VLOOKUP(A25,Other!A:E,5,0),0) -> 18 | F25: =D25+E25 -> 44318 | G25: 44318 | H25: =F25-G25 -> 0
A26: 97 | B26: 173977-4 | C26: Connector | D26: =400+2700+0+0 -> 3100 | E26: =IFERROR(VLOOKUP(A26,Other!A:E,5,0),0) -> 0 | F26: =D26+E26 -> 3100 | G26: 3100 | H26: =F26-G26 -> 0
A27: 102 | B27: 173977-7 | C27: Connector | D27: =5000+0+0+0 -> 5000 | E27: =IFERROR(VLOOKUP(A27,Other!A:E,5,0),0) -> 0 | F27: =D27+E27 -> 5000 | G27: 5000 | H27: =F27-G27 -> 0
A28: 117 | B28: 17CZ-6H | C28: Connector | D28: =1100+2650+0+6 -> 3756 | E28: =IFERROR(VLOOKUP(A28,Other!A:E,5,0),0) -> 0 | F28: =D28+E28 -> 3756 | G28: 3756 | H28: =F28-G28 -> 0
A29: 149 | B29: 2-353293-2 | C29: Connector | D29: =7340+2350+0+0 -> 9690 | E29: =IFERROR(VLOOKUP(A29,Other!A:E,5,0),0) -> 0 | F29: =D29+E29 -> 9690 | G29: 9690 | H29: =F29-G29 -> 0
A30: 151 | B30: 2-353293-3 | C30: Connector | D30: =17640+18650+0+0 -> 36290 | E30: =IFERROR(VLOOKUP(A30,Other!A:E,5,0),0) -> 0 | F30: =D30+E30 -> 36290 | G30: 36290 | H30: =F30-G30 -> 0
A31: 153 | B31: 2-353293-4 | C31: Connector | D31: =2950+3000+0+43 -> 5993 | E31: =IFERROR(VLOOKUP(A31,Other!A:E,5,0),0) -> 0 | F31: =D31+E31 -> 5993 | G31: 5993 | H31: =F31-G31 -> 0
A32: 155 | B32: 2-353293-5 | C32: Connector | D32: =1600+3600+0+0 -> 5200 | E32: =IFERROR(VLOOKUP(A32,Other!A:E,5,0),0) -> 0 | F32: =D32+E32 -> 5200 | G32: 5200 | H32: =F32-G32 -> 0
A33: 156 | B33: 2-353293-6 | C33: Connector | D33: =7580+66570+0+7 -> 74157 | E33: =IFERROR(VLOOKUP(A33,Other!A:E,5,0),0) -> 0 | F33: =D33+E33 -> 74157 | G33: 74157 | H33: =F33-G33 -> 0
A34: 158 | B34: 2-353293-7 | C34: Connector | D34: =2350+0+0+0 -> 2350 | E34: =IFERROR(VLOOKUP(A34,Other!A:E,5,0),0) -> 0 | F34: =D34+E34 -> 2350 | G34: 2350 | H34: =F34-G34 -> 0
A35: 160 | B35: 2-353293-8 | C35: Connector | D35: =3750+9550+0+0 -> 13300 | E35: =IFERROR(VLOOKUP(A35,Other!A:E,5,0),0) -> 0 | F35: =D35+E35 -> 13300 | G35: 13300 | H35: =F35-G35 -> 0
A36: 161 | B36: 31CSR-8PK(N) | C36: Connector | D36: =0+520+0+0 -> 520 | E36: =IFERROR(VLOOKUP(A36,Other!A:E,5,0),0) -> 0 | F36: =D36+E36 -> 520 | G36: 520 | H36: =F36-G36 -> 0
A37: 162 | B37: 2-353293-9 | C37: Connector | D37: =200+28500+0+0 -> 28700 | E37: =IFERROR(VLOOKUP(A37,Other!A:E,5,0),0) -> 0 | F37: =D37+E37 -> 28700 | G37: 28700 | H37: =F37-G37 -> 0
A38: 190 | B38: 15CSR-8PK(N) | C38: Connector | D38: =0+520+0+0 -> 520 | E38: =IFERROR(VLOOKUP(A38,Other!A:E,5,0),0) -> 0 | F38: =D38+E38 -> 520 | G38: 520 | H38: =F38-G38 -> 0
A39: 200 | B39: 3-353293-0 | C39: Connector | D39: =4050+950+0+30 -> 5030 | E39: =IFERROR(VLOOKUP(A39,Other!A:E,5,0),0) -> 0 | F39: =D39+E39 -> 5030 | G39: 5030 | H39: =F39-G39 -> 0
A40: 201 | B40: 3-353293-1 | C40: Connector | D40: =0+3700+0+0 -> 3700 | E40: =IFERROR(VLOOKUP(A40,Other!A:E,5,0),0) -> 0 | F40: =D40+E40 -> 3700 | G40: 3700 | H40: =F40-G40 -> 0
...
